exception calling callback for <ProcessFuture at 0x7fb7d107e7d0 state=finished raised ProcessExpired>
Traceback (most recent call last):
  File "/u/weiss/Desktop/lowcrossing_dehn/1_alexander_groups/generate_alexander_groups.sage.py", line 234, in insertion_done
    result = future.result() # blocks until done.
  File "/usr/lib/python3.10/concurrent/futures/_base.py", line 451, in result
    return self.__get_result()
  File "/usr/lib/python3.10/concurrent/futures/_base.py", line 403, in __get_result
    raise self._exception
pebble.common.ProcessExpired: Abnormal termination

During handling of the above exception, another exception occurred:

Traceback (most recent call last):
  File "/usr/lib/python3.10/concurrent/futures/_base.py", line 342, in _invoke_callbacks
    callback(self)
  File "/u/weiss/Desktop/lowcrossing_dehn/1_alexander_groups/generate_alexander_groups.sage.py", line 239, in insertion_done
    print(error.traceback)  # traceback of the function
AttributeError: 'ProcessExpired' object has no attribute 'traceback'
exception calling callback for <ProcessFuture at 0x7fb7d107e3e0 state=finished raised ProcessExpired>
Traceback (most recent call last):
  File "/u/weiss/Desktop/lowcrossing_dehn/1_alexander_groups/generate_alexander_groups.sage.py", line 234, in insertion_done
    result = future.result() # blocks until done.
  File "/usr/lib/python3.10/concurrent/futures/_base.py", line 451, in result
    return self.__get_result()
  File "/usr/lib/python3.10/concurrent/futures/_base.py", line 403, in __get_result
    raise self._exception
pebble.common.ProcessExpired: Abnormal termination

During handling of the above exception, another exception occurred:

Traceback (most recent call last):
  File "/usr/lib/python3.10/concurrent/futures/_base.py", line 342, in _invoke_callbacks
    callback(self)
  File "/u/weiss/Desktop/lowcrossing_dehn/1_alexander_groups/generate_alexander_groups.sage.py", line 239, in insertion_done
    print(error.traceback)  # traceback of the function
AttributeError: 'ProcessExpired' object has no attribute 'traceback'
exception calling callback for <ProcessFuture at 0x7fb7d107eaa0 state=finished raised ProcessExpired>
Traceback (most recent call last):
  File "/u/weiss/Desktop/lowcrossing_dehn/1_alexander_groups/generate_alexander_groups.sage.py", line 234, in insertion_done
    result = future.result() # blocks until done.
  File "/usr/lib/python3.10/concurrent/futures/_base.py", line 451, in result
    return self.__get_result()
  File "/usr/lib/python3.10/concurrent/futures/_base.py", line 403, in __get_result
    raise self._exception
pebble.common.ProcessExpired: Abnormal termination

During handling of the above exception, another exception occurred:

Traceback (most recent call last):
  File "/usr/lib/python3.10/concurrent/futures/_base.py", line 342, in _invoke_callbacks
    callback(self)
  File "/u/weiss/Desktop/lowcrossing_dehn/1_alexander_groups/generate_alexander_groups.sage.py", line 239, in insertion_done
    print(error.traceback)  # traceback of the function
AttributeError: 'ProcessExpired' object has no attribute 'traceback'
exception calling callback for <ProcessFuture at 0x7fb7d107e980 state=finished raised ProcessExpired>
Traceback (most recent call last):
  File "/u/weiss/Desktop/lowcrossing_dehn/1_alexander_groups/generate_alexander_groups.sage.py", line 234, in insertion_done
    result = future.result() # blocks until done.
  File "/usr/lib/python3.10/concurrent/futures/_base.py", line 451, in result
    return self.__get_result()
  File "/usr/lib/python3.10/concurrent/futures/_base.py", line 403, in __get_result
    raise self._exception
pebble.common.ProcessExpired: Abnormal termination

During handling of the above exception, another exception occurred:

Traceback (most recent call last):
  File "/usr/lib/python3.10/concurrent/futures/_base.py", line 342, in _invoke_callbacks
    callback(self)
  File "/u/weiss/Desktop/lowcrossing_dehn/1_alexander_groups/generate_alexander_groups.sage.py", line 239, in insertion_done
    print(error.traceback)  # traceback of the function
AttributeError: 'ProcessExpired' object has no attribute 'traceback'
exception calling callback for <ProcessFuture at 0x7fb7d107f700 state=finished raised ProcessExpired>
Traceback (most recent call last):
  File "/u/weiss/Desktop/lowcrossing_dehn/1_alexander_groups/generate_alexander_groups.sage.py", line 234, in insertion_done
    result = future.result() # blocks until done.
  File "/usr/lib/python3.10/concurrent/futures/_base.py", line 451, in result
    return self.__get_result()
  File "/usr/lib/python3.10/concurrent/futures/_base.py", line 403, in __get_result
    raise self._exception
pebble.common.ProcessExpired: Abnormal termination

During handling of the above exception, another exception occurred:

Traceback (most recent call last):
  File "/usr/lib/python3.10/concurrent/futures/_base.py", line 342, in _invoke_callbacks
    callback(self)
  File "/u/weiss/Desktop/lowcrossing_dehn/1_alexander_groups/generate_alexander_groups.sage.py", line 239, in insertion_done
    print(error.traceback)  # traceback of the function
AttributeError: 'ProcessExpired' object has no attribute 'traceback'
exception calling callback for <ProcessFuture at 0x7fb7d107f550 state=finished raised ProcessExpired>
Traceback (most recent call last):
  File "/u/weiss/Desktop/lowcrossing_dehn/1_alexander_groups/generate_alexander_groups.sage.py", line 234, in insertion_done
    result = future.result() # blocks until done.
  File "/usr/lib/python3.10/concurrent/futures/_base.py", line 451, in result
    return self.__get_result()
  File "/usr/lib/python3.10/concurrent/futures/_base.py", line 403, in __get_result
    raise self._exception
pebble.common.ProcessExpired: Abnormal termination

During handling of the above exception, another exception occurred:

Traceback (most recent call last):
  File "/usr/lib/python3.10/concurrent/futures/_base.py", line 342, in _invoke_callbacks
    callback(self)
  File "/u/weiss/Desktop/lowcrossing_dehn/1_alexander_groups/generate_alexander_groups.sage.py", line 239, in insertion_done
    print(error.traceback)  # traceback of the function
AttributeError: 'ProcessExpired' object has no attribute 'traceback'
exception calling callback for <ProcessFuture at 0x7fb7d107fa60 state=finished raised ProcessExpired>
Traceback (most recent call last):
  File "/u/weiss/Desktop/lowcrossing_dehn/1_alexander_groups/generate_alexander_groups.sage.py", line 234, in insertion_done
    result = future.result() # blocks until done.
  File "/usr/lib/python3.10/concurrent/futures/_base.py", line 451, in result
    return self.__get_result()
  File "/usr/lib/python3.10/concurrent/futures/_base.py", line 403, in __get_result
    raise self._exception
pebble.common.ProcessExpired: Abnormal termination

During handling of the above exception, another exception occurred:

Traceback (most recent call last):
  File "/usr/lib/python3.10/concurrent/futures/_base.py", line 342, in _invoke_callbacks
    callback(self)
  File "/u/weiss/Desktop/lowcrossing_dehn/1_alexander_groups/generate_alexander_groups.sage.py", line 239, in insertion_done
    print(error.traceback)  # traceback of the function
AttributeError: 'ProcessExpired' object has no attribute 'traceback'
exception calling callback for <ProcessFuture at 0x7fb7d107f5e0 state=finished raised ProcessExpired>
Traceback (most recent call last):
  File "/u/weiss/Desktop/lowcrossing_dehn/1_alexander_groups/generate_alexander_groups.sage.py", line 234, in insertion_done
    result = future.result() # blocks until done.
  File "/usr/lib/python3.10/concurrent/futures/_base.py", line 451, in result
    return self.__get_result()
  File "/usr/lib/python3.10/concurrent/futures/_base.py", line 403, in __get_result
    raise self._exception
pebble.common.ProcessExpired: Abnormal termination

During handling of the above exception, another exception occurred:

Traceback (most recent call last):
  File "/usr/lib/python3.10/concurrent/futures/_base.py", line 342, in _invoke_callbacks
    callback(self)
  File "/u/weiss/Desktop/lowcrossing_dehn/1_alexander_groups/generate_alexander_groups.sage.py", line 239, in insertion_done
    print(error.traceback)  # traceback of the function
AttributeError: 'ProcessExpired' object has no attribute 'traceback'
exception calling callback for <ProcessFuture at 0x7fb7d107f820 state=finished raised ProcessExpired>
Traceback (most recent call last):
  File "/u/weiss/Desktop/lowcrossing_dehn/1_alexander_groups/generate_alexander_groups.sage.py", line 234, in insertion_done
    result = future.result() # blocks until done.
  File "/usr/lib/python3.10/concurrent/futures/_base.py", line 451, in result
    return self.__get_result()
  File "/usr/lib/python3.10/concurrent/futures/_base.py", line 403, in __get_result
    raise self._exception
pebble.common.ProcessExpired: Abnormal termination

During handling of the above exception, another exception occurred:

Traceback (most recent call last):
  File "/usr/lib/python3.10/concurrent/futures/_base.py", line 342, in _invoke_callbacks
    callback(self)
  File "/u/weiss/Desktop/lowcrossing_dehn/1_alexander_groups/generate_alexander_groups.sage.py", line 239, in insertion_done
    print(error.traceback)  # traceback of the function
AttributeError: 'ProcessExpired' object has no attribute 'traceback'
exception calling callback for <ProcessFuture at 0x7fb7d107f670 state=finished raised ProcessExpired>
Traceback (most recent call last):
  File "/u/weiss/Desktop/lowcrossing_dehn/1_alexander_groups/generate_alexander_groups.sage.py", line 234, in insertion_done
    result = future.result() # blocks until done.
  File "/usr/lib/python3.10/concurrent/futures/_base.py", line 451, in result
    return self.__get_result()
  File "/usr/lib/python3.10/concurrent/futures/_base.py", line 403, in __get_result
    raise self._exception
pebble.common.ProcessExpired: Abnormal termination

During handling of the above exception, another exception occurred:

Traceback (most recent call last):
  File "/usr/lib/python3.10/concurrent/futures/_base.py", line 342, in _invoke_callbacks
    callback(self)
  File "/u/weiss/Desktop/lowcrossing_dehn/1_alexander_groups/generate_alexander_groups.sage.py", line 239, in insertion_done
    print(error.traceback)  # traceback of the function
AttributeError: 'ProcessExpired' object has no attribute 'traceback'
exception calling callback for <ProcessFuture at 0x7fb7d10ac310 state=finished raised ProcessExpired>
Traceback (most recent call last):
  File "/u/weiss/Desktop/lowcrossing_dehn/1_alexander_groups/generate_alexander_groups.sage.py", line 234, in insertion_done
    result = future.result() # blocks until done.
  File "/usr/lib/python3.10/concurrent/futures/_base.py", line 451, in result
    return self.__get_result()
  File "/usr/lib/python3.10/concurrent/futures/_base.py", line 403, in __get_result
    raise self._exception
pebble.common.ProcessExpired: Abnormal termination

During handling of the above exception, another exception occurred:

Traceback (most recent call last):
  File "/usr/lib/python3.10/concurrent/futures/_base.py", line 342, in _invoke_callbacks
    callback(self)
  File "/u/weiss/Desktop/lowcrossing_dehn/1_alexander_groups/generate_alexander_groups.sage.py", line 239, in insertion_done
    print(error.traceback)  # traceback of the function
AttributeError: 'ProcessExpired' object has no attribute 'traceback'
exception calling callback for <ProcessFuture at 0x7fb7d10ac4c0 state=finished raised ProcessExpired>
Traceback (most recent call last):
  File "/u/weiss/Desktop/lowcrossing_dehn/1_alexander_groups/generate_alexander_groups.sage.py", line 234, in insertion_done
    result = future.result() # blocks until done.
  File "/usr/lib/python3.10/concurrent/futures/_base.py", line 451, in result
    return self.__get_result()
  File "/usr/lib/python3.10/concurrent/futures/_base.py", line 403, in __get_result
    raise self._exception
pebble.common.ProcessExpired: Abnormal termination

During handling of the above exception, another exception occurred:

Traceback (most recent call last):
  File "/usr/lib/python3.10/concurrent/futures/_base.py", line 342, in _invoke_callbacks
    callback(self)
  File "/u/weiss/Desktop/lowcrossing_dehn/1_alexander_groups/generate_alexander_groups.sage.py", line 239, in insertion_done
    print(error.traceback)  # traceback of the function
AttributeError: 'ProcessExpired' object has no attribute 'traceback'
exception calling callback for <ProcessFuture at 0x7fb7d10ac670 state=finished raised ProcessExpired>
Traceback (most recent call last):
  File "/u/weiss/Desktop/lowcrossing_dehn/1_alexander_groups/generate_alexander_groups.sage.py", line 234, in insertion_done
    result = future.result() # blocks until done.
  File "/usr/lib/python3.10/concurrent/futures/_base.py", line 451, in result
    return self.__get_result()
  File "/usr/lib/python3.10/concurrent/futures/_base.py", line 403, in __get_result
    raise self._exception
pebble.common.ProcessExpired: Abnormal termination

During handling of the above exception, another exception occurred:

Traceback (most recent call last):
  File "/usr/lib/python3.10/concurrent/futures/_base.py", line 342, in _invoke_callbacks
    callback(self)
  File "/u/weiss/Desktop/lowcrossing_dehn/1_alexander_groups/generate_alexander_groups.sage.py", line 239, in insertion_done
    print(error.traceback)  # traceback of the function
AttributeError: 'ProcessExpired' object has no attribute 'traceback'
exception calling callback for <ProcessFuture at 0x7fb7d10acf70 state=finished raised ProcessExpired>
Traceback (most recent call last):
  File "/u/weiss/Desktop/lowcrossing_dehn/1_alexander_groups/generate_alexander_groups.sage.py", line 234, in insertion_done
    result = future.result() # blocks until done.
  File "/usr/lib/python3.10/concurrent/futures/_base.py", line 451, in result
    return self.__get_result()
  File "/usr/lib/python3.10/concurrent/futures/_base.py", line 403, in __get_result
    raise self._exception
pebble.common.ProcessExpired: Abnormal termination

During handling of the above exception, another exception occurred:

Traceback (most recent call last):
  File "/usr/lib/python3.10/concurrent/futures/_base.py", line 342, in _invoke_callbacks
    callback(self)
  File "/u/weiss/Desktop/lowcrossing_dehn/1_alexander_groups/generate_alexander_groups.sage.py", line 239, in insertion_done
    print(error.traceback)  # traceback of the function
AttributeError: 'ProcessExpired' object has no attribute 'traceback'
exception calling callback for <ProcessFuture at 0x7fb7d10aca60 state=finished raised ProcessExpired>
Traceback (most recent call last):
  File "/u/weiss/Desktop/lowcrossing_dehn/1_alexander_groups/generate_alexander_groups.sage.py", line 234, in insertion_done
    result = future.result() # blocks until done.
  File "/usr/lib/python3.10/concurrent/futures/_base.py", line 451, in result
    return self.__get_result()
  File "/usr/lib/python3.10/concurrent/futures/_base.py", line 403, in __get_result
    raise self._exception
pebble.common.ProcessExpired: Abnormal termination

During handling of the above exception, another exception occurred:

Traceback (most recent call last):
  File "/usr/lib/python3.10/concurrent/futures/_base.py", line 342, in _invoke_callbacks
    callback(self)
  File "/u/weiss/Desktop/lowcrossing_dehn/1_alexander_groups/generate_alexander_groups.sage.py", line 239, in insertion_done
    print(error.traceback)  # traceback of the function
AttributeError: 'ProcessExpired' object has no attribute 'traceback'
exception calling callback for <ProcessFuture at 0x7fb75487e440 state=finished raised ProcessExpired>
Traceback (most recent call last):
  File "/u/weiss/Desktop/lowcrossing_dehn/1_alexander_groups/generate_alexander_groups.sage.py", line 234, in insertion_done
    result = future.result() # blocks until done.
  File "/usr/lib/python3.10/concurrent/futures/_base.py", line 451, in result
    return self.__get_result()
  File "/usr/lib/python3.10/concurrent/futures/_base.py", line 403, in __get_result
    raise self._exception
pebble.common.ProcessExpired: Abnormal termination

During handling of the above exception, another exception occurred:

Traceback (most recent call last):
  File "/usr/lib/python3.10/concurrent/futures/_base.py", line 342, in _invoke_callbacks
    callback(self)
  File "/u/weiss/Desktop/lowcrossing_dehn/1_alexander_groups/generate_alexander_groups.sage.py", line 239, in insertion_done
    print(error.traceback)  # traceback of the function
AttributeError: 'ProcessExpired' object has no attribute 'traceback'
exception calling callback for <ProcessFuture at 0x7fb75487e830 state=finished raised ProcessExpired>
Traceback (most recent call last):
  File "/u/weiss/Desktop/lowcrossing_dehn/1_alexander_groups/generate_alexander_groups.sage.py", line 234, in insertion_done
    result = future.result() # blocks until done.
  File "/usr/lib/python3.10/concurrent/futures/_base.py", line 451, in result
    return self.__get_result()
  File "/usr/lib/python3.10/concurrent/futures/_base.py", line 403, in __get_result
    raise self._exception
pebble.common.ProcessExpired: Abnormal termination

During handling of the above exception, another exception occurred:

Traceback (most recent call last):
  File "/usr/lib/python3.10/concurrent/futures/_base.py", line 342, in _invoke_callbacks
    callback(self)
  File "/u/weiss/Desktop/lowcrossing_dehn/1_alexander_groups/generate_alexander_groups.sage.py", line 239, in insertion_done
    print(error.traceback)  # traceback of the function
AttributeError: 'ProcessExpired' object has no attribute 'traceback'
exception calling callback for <ProcessFuture at 0x7fb75487eb00 state=finished raised ProcessExpired>
Traceback (most recent call last):
  File "/u/weiss/Desktop/lowcrossing_dehn/1_alexander_groups/generate_alexander_groups.sage.py", line 234, in insertion_done
    result = future.result() # blocks until done.
  File "/usr/lib/python3.10/concurrent/futures/_base.py", line 451, in result
    return self.__get_result()
  File "/usr/lib/python3.10/concurrent/futures/_base.py", line 403, in __get_result
    raise self._exception
pebble.common.ProcessExpired: Abnormal termination

During handling of the above exception, another exception occurred:

Traceback (most recent call last):
  File "/usr/lib/python3.10/concurrent/futures/_base.py", line 342, in _invoke_callbacks
    callback(self)
  File "/u/weiss/Desktop/lowcrossing_dehn/1_alexander_groups/generate_alexander_groups.sage.py", line 239, in insertion_done
    print(error.traceback)  # traceback of the function
AttributeError: 'ProcessExpired' object has no attribute 'traceback'
exception calling callback for <ProcessFuture at 0x7fb75487e9e0 state=finished raised ProcessExpired>
Traceback (most recent call last):
  File "/u/weiss/Desktop/lowcrossing_dehn/1_alexander_groups/generate_alexander_groups.sage.py", line 234, in insertion_done
    result = future.result() # blocks until done.
  File "/usr/lib/python3.10/concurrent/futures/_base.py", line 451, in result
    return self.__get_result()
  File "/usr/lib/python3.10/concurrent/futures/_base.py", line 403, in __get_result
    raise self._exception
pebble.common.ProcessExpired: Abnormal termination

During handling of the above exception, another exception occurred:

Traceback (most recent call last):
  File "/usr/lib/python3.10/concurrent/futures/_base.py", line 342, in _invoke_callbacks
    callback(self)
  File "/u/weiss/Desktop/lowcrossing_dehn/1_alexander_groups/generate_alexander_groups.sage.py", line 239, in insertion_done
    print(error.traceback)  # traceback of the function
AttributeError: 'ProcessExpired' object has no attribute 'traceback'
exception calling callback for <ProcessFuture at 0x7fb75487e8c0 state=finished raised ProcessExpired>
Traceback (most recent call last):
  File "/u/weiss/Desktop/lowcrossing_dehn/1_alexander_groups/generate_alexander_groups.sage.py", line 234, in insertion_done
    result = future.result() # blocks until done.
  File "/usr/lib/python3.10/concurrent/futures/_base.py", line 451, in result
    return self.__get_result()
  File "/usr/lib/python3.10/concurrent/futures/_base.py", line 403, in __get_result
    raise self._exception
pebble.common.ProcessExpired: Abnormal termination

During handling of the above exception, another exception occurred:

Traceback (most recent call last):
  File "/usr/lib/python3.10/concurrent/futures/_base.py", line 342, in _invoke_callbacks
    callback(self)
  File "/u/weiss/Desktop/lowcrossing_dehn/1_alexander_groups/generate_alexander_groups.sage.py", line 239, in insertion_done
    print(error.traceback)  # traceback of the function
AttributeError: 'ProcessExpired' object has no attribute 'traceback'
exception calling callback for <ProcessFuture at 0x7fb75487ec20 state=finished raised ProcessExpired>
Traceback (most recent call last):
  File "/u/weiss/Desktop/lowcrossing_dehn/1_alexander_groups/generate_alexander_groups.sage.py", line 234, in insertion_done
    result = future.result() # blocks until done.
  File "/usr/lib/python3.10/concurrent/futures/_base.py", line 451, in result
    return self.__get_result()
  File "/usr/lib/python3.10/concurrent/futures/_base.py", line 403, in __get_result
    raise self._exception
pebble.common.ProcessExpired: Abnormal termination

During handling of the above exception, another exception occurred:

Traceback (most recent call last):
  File "/usr/lib/python3.10/concurrent/futures/_base.py", line 342, in _invoke_callbacks
    callback(self)
  File "/u/weiss/Desktop/lowcrossing_dehn/1_alexander_groups/generate_alexander_groups.sage.py", line 239, in insertion_done
    print(error.traceback)  # traceback of the function
AttributeError: 'ProcessExpired' object has no attribute 'traceback'
exception calling callback for <ProcessFuture at 0x7fb75487e3b0 state=finished raised ProcessExpired>
Traceback (most recent call last):
  File "/u/weiss/Desktop/lowcrossing_dehn/1_alexander_groups/generate_alexander_groups.sage.py", line 234, in insertion_done
    result = future.result() # blocks until done.
  File "/usr/lib/python3.10/concurrent/futures/_base.py", line 451, in result
    return self.__get_result()
  File "/usr/lib/python3.10/concurrent/futures/_base.py", line 403, in __get_result
    raise self._exception
pebble.common.ProcessExpired: Abnormal termination

During handling of the above exception, another exception occurred:

Traceback (most recent call last):
  File "/usr/lib/python3.10/concurrent/futures/_base.py", line 342, in _invoke_callbacks
    callback(self)
  File "/u/weiss/Desktop/lowcrossing_dehn/1_alexander_groups/generate_alexander_groups.sage.py", line 239, in insertion_done
    print(error.traceback)  # traceback of the function
AttributeError: 'ProcessExpired' object has no attribute 'traceback'
exception calling callback for <ProcessFuture at 0x7fb75487eb90 state=finished raised ProcessExpired>
Traceback (most recent call last):
  File "/u/weiss/Desktop/lowcrossing_dehn/1_alexander_groups/generate_alexander_groups.sage.py", line 234, in insertion_done
    result = future.result() # blocks until done.
  File "/usr/lib/python3.10/concurrent/futures/_base.py", line 451, in result
    return self.__get_result()
  File "/usr/lib/python3.10/concurrent/futures/_base.py", line 403, in __get_result
    raise self._exception
pebble.common.ProcessExpired: Abnormal termination

During handling of the above exception, another exception occurred:

Traceback (most recent call last):
  File "/usr/lib/python3.10/concurrent/futures/_base.py", line 342, in _invoke_callbacks
    callback(self)
  File "/u/weiss/Desktop/lowcrossing_dehn/1_alexander_groups/generate_alexander_groups.sage.py", line 239, in insertion_done
    print(error.traceback)  # traceback of the function
AttributeError: 'ProcessExpired' object has no attribute 'traceback'
exception calling callback for <ProcessFuture at 0x7fb75487ecb0 state=finished raised ProcessExpired>
Traceback (most recent call last):
  File "/u/weiss/Desktop/lowcrossing_dehn/1_alexander_groups/generate_alexander_groups.sage.py", line 234, in insertion_done
    result = future.result() # blocks until done.
  File "/usr/lib/python3.10/concurrent/futures/_base.py", line 451, in result
    return self.__get_result()
  File "/usr/lib/python3.10/concurrent/futures/_base.py", line 403, in __get_result
    raise self._exception
pebble.common.ProcessExpired: Abnormal termination

During handling of the above exception, another exception occurred:

Traceback (most recent call last):
  File "/usr/lib/python3.10/concurrent/futures/_base.py", line 342, in _invoke_callbacks
    callback(self)
  File "/u/weiss/Desktop/lowcrossing_dehn/1_alexander_groups/generate_alexander_groups.sage.py", line 239, in insertion_done
    print(error.traceback)  # traceback of the function
AttributeError: 'ProcessExpired' object has no attribute 'traceback'
exception calling callback for <ProcessFuture at 0x7fb75487e950 state=finished raised ProcessExpired>
Traceback (most recent call last):
  File "/u/weiss/Desktop/lowcrossing_dehn/1_alexander_groups/generate_alexander_groups.sage.py", line 234, in insertion_done
    result = future.result() # blocks until done.
  File "/usr/lib/python3.10/concurrent/futures/_base.py", line 451, in result
    return self.__get_result()
  File "/usr/lib/python3.10/concurrent/futures/_base.py", line 403, in __get_result
    raise self._exception
pebble.common.ProcessExpired: Abnormal termination

During handling of the above exception, another exception occurred:

Traceback (most recent call last):
  File "/usr/lib/python3.10/concurrent/futures/_base.py", line 342, in _invoke_callbacks
    callback(self)
  File "/u/weiss/Desktop/lowcrossing_dehn/1_alexander_groups/generate_alexander_groups.sage.py", line 239, in insertion_done
    print(error.traceback)  # traceback of the function
AttributeError: 'ProcessExpired' object has no attribute 'traceback'
exception calling callback for <ProcessFuture at 0x7fb75487e680 state=finished raised ProcessExpired>
Traceback (most recent call last):
  File "/u/weiss/Desktop/lowcrossing_dehn/1_alexander_groups/generate_alexander_groups.sage.py", line 234, in insertion_done
    result = future.result() # blocks until done.
  File "/usr/lib/python3.10/concurrent/futures/_base.py", line 451, in result
    return self.__get_result()
  File "/usr/lib/python3.10/concurrent/futures/_base.py", line 403, in __get_result
    raise self._exception
pebble.common.ProcessExpired: Abnormal termination

During handling of the above exception, another exception occurred:

Traceback (most recent call last):
  File "/usr/lib/python3.10/concurrent/futures/_base.py", line 342, in _invoke_callbacks
    callback(self)
  File "/u/weiss/Desktop/lowcrossing_dehn/1_alexander_groups/generate_alexander_groups.sage.py", line 239, in insertion_done
    print(error.traceback)  # traceback of the function
AttributeError: 'ProcessExpired' object has no attribute 'traceback'
exception calling callback for <ProcessFuture at 0x7fb75487ee60 state=finished raised ProcessExpired>
Traceback (most recent call last):
  File "/u/weiss/Desktop/lowcrossing_dehn/1_alexander_groups/generate_alexander_groups.sage.py", line 234, in insertion_done
    result = future.result() # blocks until done.
  File "/usr/lib/python3.10/concurrent/futures/_base.py", line 451, in result
    return self.__get_result()
  File "/usr/lib/python3.10/concurrent/futures/_base.py", line 403, in __get_result
    raise self._exception
pebble.common.ProcessExpired: Abnormal termination

During handling of the above exception, another exception occurred:

Traceback (most recent call last):
  File "/usr/lib/python3.10/concurrent/futures/_base.py", line 342, in _invoke_callbacks
    callback(self)
  File "/u/weiss/Desktop/lowcrossing_dehn/1_alexander_groups/generate_alexander_groups.sage.py", line 239, in insertion_done
    print(error.traceback)  # traceback of the function
AttributeError: 'ProcessExpired' object has no attribute 'traceback'
exception calling callback for <ProcessFuture at 0x7fb75487e7a0 state=finished raised ProcessExpired>
Traceback (most recent call last):
  File "/u/weiss/Desktop/lowcrossing_dehn/1_alexander_groups/generate_alexander_groups.sage.py", line 234, in insertion_done
    result = future.result() # blocks until done.
  File "/usr/lib/python3.10/concurrent/futures/_base.py", line 451, in result
    return self.__get_result()
  File "/usr/lib/python3.10/concurrent/futures/_base.py", line 403, in __get_result
    raise self._exception
pebble.common.ProcessExpired: Abnormal termination

During handling of the above exception, another exception occurred:

Traceback (most recent call last):
  File "/usr/lib/python3.10/concurrent/futures/_base.py", line 342, in _invoke_callbacks
    callback(self)
  File "/u/weiss/Desktop/lowcrossing_dehn/1_alexander_groups/generate_alexander_groups.sage.py", line 239, in insertion_done
    print(error.traceback)  # traceback of the function
AttributeError: 'ProcessExpired' object has no attribute 'traceback'
exception calling callback for <ProcessFuture at 0x7fb75487f0a0 state=finished raised ProcessExpired>
Traceback (most recent call last):
  File "/u/weiss/Desktop/lowcrossing_dehn/1_alexander_groups/generate_alexander_groups.sage.py", line 234, in insertion_done
    result = future.result() # blocks until done.
  File "/usr/lib/python3.10/concurrent/futures/_base.py", line 451, in result
    return self.__get_result()
  File "/usr/lib/python3.10/concurrent/futures/_base.py", line 403, in __get_result
    raise self._exception
pebble.common.ProcessExpired: Abnormal termination

During handling of the above exception, another exception occurred:

Traceback (most recent call last):
  File "/usr/lib/python3.10/concurrent/futures/_base.py", line 342, in _invoke_callbacks
    callback(self)
  File "/u/weiss/Desktop/lowcrossing_dehn/1_alexander_groups/generate_alexander_groups.sage.py", line 239, in insertion_done
    print(error.traceback)  # traceback of the function
AttributeError: 'ProcessExpired' object has no attribute 'traceback'
exception calling callback for <ProcessFuture at 0x7fb75487ea70 state=finished raised ProcessExpired>
Traceback (most recent call last):
  File "/u/weiss/Desktop/lowcrossing_dehn/1_alexander_groups/generate_alexander_groups.sage.py", line 234, in insertion_done
    result = future.result() # blocks until done.
  File "/usr/lib/python3.10/concurrent/futures/_base.py", line 451, in result
    return self.__get_result()
  File "/usr/lib/python3.10/concurrent/futures/_base.py", line 403, in __get_result
    raise self._exception
pebble.common.ProcessExpired: Abnormal termination

During handling of the above exception, another exception occurred:

Traceback (most recent call last):
  File "/usr/lib/python3.10/concurrent/futures/_base.py", line 342, in _invoke_callbacks
    callback(self)
  File "/u/weiss/Desktop/lowcrossing_dehn/1_alexander_groups/generate_alexander_groups.sage.py", line 239, in insertion_done
    print(error.traceback)  # traceback of the function
AttributeError: 'ProcessExpired' object has no attribute 'traceback'
exception calling callback for <ProcessFuture at 0x7fb7548aef50 state=finished raised ProcessExpired>
Traceback (most recent call last):
  File "/u/weiss/Desktop/lowcrossing_dehn/1_alexander_groups/generate_alexander_groups.sage.py", line 234, in insertion_done
    result = future.result() # blocks until done.
  File "/usr/lib/python3.10/concurrent/futures/_base.py", line 451, in result
    return self.__get_result()
  File "/usr/lib/python3.10/concurrent/futures/_base.py", line 403, in __get_result
    raise self._exception
pebble.common.ProcessExpired: Abnormal termination

During handling of the above exception, another exception occurred:

Traceback (most recent call last):
  File "/usr/lib/python3.10/concurrent/futures/_base.py", line 342, in _invoke_callbacks
    callback(self)
  File "/u/weiss/Desktop/lowcrossing_dehn/1_alexander_groups/generate_alexander_groups.sage.py", line 239, in insertion_done
    print(error.traceback)  # traceback of the function
AttributeError: 'ProcessExpired' object has no attribute 'traceback'
Traceback (most recent call last):
  File "/u/weiss/Desktop/lowcrossing_dehn/1_alexander_groups/generate_alexander_groups.sage.py", line 253, in process_burton_list
Terminated
/usr/lib/python3.10/multiprocessing/resource_tracker.py:224: UserWarning: resource_tracker: There appear to be 2 leaked shared_memory objects to clean up at shutdown
  warnings.warn('resource_tracker: There appear to be %d '
